Workbook

Sheet Config_Directory
A1: TAMHA TEAMS & DIVISIONS DIRECTORY
A2: Official source of truth for dropdowns, validation, and reporting.
A4: Division | B4: Team / Level | C4: Display Label | D4: Category | F4: ICE STATUS CATEGORIES | G4: Color Code | H4: Description | J4: VENUES / RINKS
A5: U7 | B5: U7-4 | C5: U7 - Group 4 | D5: Team | F5: Open / Available | H5: Unassigned ice open for teams to claim/purchase | J5: Truro Stadium
A6: U7 | B6: U7-5 Blue | C6: U7 - 5 Blue | D6: Team | F6: Booked: Practice | H6: Confirmed regular practice ice | J6: RECC
A7: U7 | B7: U7-5 Orange | C7: U7 - 5 Orange | D7: Team | F7: Booked: Home Game | H7: Confirmed league/exhibition home game | J7: Deuvilles
A8: U7 | B8: U7-6 | C8: U7 - Group 6 | D8: Team | F8: Tentative Hold | H8: Temporarily reserved, awaiting confirmation | J8: Debert Arena
A9: U9 | B9: U9 Intermediate | C9: U9 - Intermediate | D9: Team | F9: Released / Dead Ice | H9: Slot cancelled or returned to arena | J9: Tatamagouche
A10: U9 | B10: U9 Advanced | C10: U9 - Advanced | D10: Team | F10: TAMHA Development | H10: Association-wide skills/goalie/referee sessions | J10: Oxford Arena
A11: U9 | B11: U9 Jayasinghe | C11: U9 - Jayasinghe | D11: Team | F11: Arena Conflict | H11: External event (Jr A Bearcats, maintenance, outage)
A12: U9 | B12: U9 John | C12: U9 - John | D12: Team
A13: U11 | B13: U11 AA | C13: U11 AA | D13: Team
A14: U11 | B14: U11 A | C14: U11 A | D14: Team
A15: U11 | B15: U11 B | C15: U11 B | D15: Team
A16: U11 | B16: U11 C Bernard | C16: U11 C - Bernard | D16: Team
A17: U11 | B17: U11 C Simms | C17: U11 C - Simms | D17: Team
A18: U13 | B18: U13 AAA | C18: U13 AAA | D18: Team
A19: U13 | B19: U13 AA | C19: U13 AA | D19: Team
A20: U13 | B20: U13 A Malone | C20: U13 A - Malone | D20: Team
A21: U13 | B21: U13 B | C21: U13 B | D21: Team
A22: U13 | B22: U13 C Campbell | C22: U13 C - Campbell | D22: Team
A23: U13 | B23: U13 C Cameron | C23: U13 C - Cameron | D23: Team
... A38: External | B38: High School Hockey | C38: External - High School | D38: External

Sheet Weekday_Template
B1: TAMHA WEEKDAY ICE SCHEDULE
B2: Week: Monday to Friday
B4: VENUE: TRURO STADIUM
B5: Monday | E5: Tuesday | H5: Wednesday | K5: Thursday | N5: Friday
B6: Time | C6: Team / User | D6: Status | E6: Time | F6: Team / User | G6: Status | H6: Time | I6: Team / User | J6: Status | K6: Time | L6: Team / User | M6: Status | N6: Time | O6: Team / User | P6: Status
B7: 5:00-5:50 | D7: Open / Available | E7: 5:00-5:50 | G7: Open / Available | H7: 5:00-5:50 | J7: Open / Available | K7: 5:00-5:50 | M7: Open / Available | N7: 5:00-5:50 | P7: Open / Available
B8: 6:00-6:50 | D8: Open / Available | E8: 6:00-6:50 | G8: Open / Available | H8: 6:00-6:50 | J8: Open / Available | K8: 6:00-6:50 | M8: Open / Available | N8: 6:00-6:50 | P8: Open / Available
B9: 7:00-7:50 | D9: Open / Available | E9: 7:00-7:50 | G9: Open / Available | H9: 7:00-7:50 | J9: Open / Available | K9: 7:00-7:50 | M9: Open / Available | N9: 7:00-7:50 | P9: Open / Available
B10: 8:00-8:50 | D10: Open / Available | E10: 8:00-8:50 | G10: Open / Available | H10: 8:00-8:50 | J10: Open / Available | K10: 8:00-8:50 | M10: Open / Available | N10: 8:00-8:50 | P10: Open / Available
B11: 9:00-9:50 | D11: Open / Available | E11: 9:00-9:50 | G11: Open / Available | H11: 9:00-9:50 | J11: Open / Available | K11: 9:00-9:50 | M11: Open / Available | N11: 9:00-9:50 | P11: Open / Available
B12: 10:00-10:50 | D12: Open / Available | E12: 10:00-10:50 | G12: Open / Available | H12: 10:00-10:50 | J12: Open / Available | K12: 10:00-10:50 | M12: Open / Available | N12: 10:00-10:50 | P12: Open / Available
B14: VENUE: RECC
B15: Monday | E15: Tuesday | H15: Wednesday | K15: Thursday | N15: Friday
B16: Time | C16: Team / User | D16: Status | E16: Time | F16: Team / User | G16: Status | H16: Time | I16: Team / User | J16: Status | K16: Time | L16: Team / User | M16: Status | N16: Time | O16: Team / User | P16: Status
B17: 5:00-5:50 | D17: Open / Available | E17: 5:00-5:50 | G17: Open / Available | H17: 5:00-5:50 | J17: Open / Available | K17: 5:00-5:50 | M17: Open / Available | N17: 5:00-5:50 | P17: Open / Available
B18: 6:00-6:50 | D18: Open / Available | E18: 6:00-6:50 | G18: Open / Available | H18: 6:00-6:50 | J18: Open / Available | K18: 6:00-6:50 | M18: Open / Available | N18: 6:00-6:50 | P18: Open / Available
B19: 7:00-7:50 | D19: Open / Available | E19: 7:00-7:50 | G19: Open / Available | H19: 7:00-7:50 | J19: Open / Available | K19: 7:00-7:50 | M19: Open / Available | N19: 7:00-7:50 | P19: Open / Available
B20: 8:00-8:50 | D20: Open / Available | E20: 8:00-8:50 | G20: Open / Available | H20: 8:00-8:50 | J20: Open / Available | K20: 8:00-8:50 | M20: Open / Available | N20: 8:00-8:50 | P20: Open / Available
B21: 9:00-9:50 | D21: Open / Available | E21: 9:00-9:50 | G21: Open / Available | H21: 9:00-9:50 | J21: Open / Available | K21: 9:00-9:50 | M21: Open / Available | N21: 9:00-9:50 | P21: Open / Available
B22: 10:00-10:50 | D22: Open / Available | E22: 10:00-10:50 | G22: Open / Available | H22: 10:00-10:50 | J22: Open / Available | K22: 10:00-10:50 | M22: Open / Available | N22: 10:00-10:50 | P22: Open / Available
B24: VENUE: DEUVILLES
B25: Monday | E25: Tuesday | H25: Wednesday | K25: Thursday | N25: Friday
B26: Time | C26: Team / User | D26: Status | E26: Time | F26: Team / User | G26: Status | H26: Time | I26: Team / User | J26: Status | K26: Time | L26: Team / User | M26: Status | N26: Time | O26: Team / User | P26: Status
B27: 5:00-5:50 | D27: Open / Available | E27: 5:00-5:50 | G27: Open / Available | H27: 5:00-5:50 | J27: Open / Available | K27: 5:00-5:50 | M27: Open / Available | N27: 5:00-5:50 | P27: Open / Available
B28: 6:00-6:50 | D28: Open / Available | E28: 6:00-6:50 | G28: Open / Available | H28: 6:00-6:50 | J28: Open / Available | K28: 6:00-6:50 | M28: Open / Available | N28: 6:00-6:50 | P28: Open / Available
B29: 7:00-7:50 | D29: Open / Available | E29: 7:00-7:50 | G29: Open / Available | H29: 7:00-7:50 | J29: Open / Available | K29: 7:00-7:50 | M29: Open / Available | N29: 7:00-7:50 | P29: Open / Available
B30: 8:00-8:50 | D30: Open / Available | E30: 8:00-8:50 | G30: Open / Available | H30: 8:00-8:50 | J30: Open / Available | K30: 8:00-8:50 | M30: Open / Available | N30: 8:00-8:50 | P30: Open / Available
B31: 9:00-9:50 | D31: Open / Available | E31: 9:00-9:50 | G31: Open / Available | H31: 9:00-9:50 | J31: Open / Available | K31: 9:00-9:50 | M31: Open / Available | N31: 9:00-9:50 | P31: Open / Available
B32: 10:00-10:50 | D32: Open / Available | E32: 10:00-10:50 | G32: Open / Available | H32: 10:00-10:50 | J32: Open / Available | K32: 10:00-10:50 | M32: Open / Available | N32: 10:00-10:50 | P32: Open / Available
B34: VENUE: DEBERT ARENA
B35: Monday | E35: Tuesday | H35: Wednesday | K35: Thursday | N35: Friday
B36: Time | C36: Team / User | D36: Status | E36: Time | F36: Team / User | G36: Status | H36: Time | I36: Team / User | J36: Status | K36: Time | L36: Team / User | M36: Status | N36: Time | O36: Team / User | P36: Status
B37: 5:00-5:50 | D37: Open / Available | E37: 5:00-5:50 | G37: Open / Available | H37: 5:00-5:50 | J37: Open / Available | K37: 5:00-5:50 | M37: Open / Available | N37: 5:00-5:50 | P37: Open / Available
B38: 6:00-6:50 | D38: Open / Available | E38: 6:00-6:50 | G38: Open / Available | H38: 6:00-6:50 | J38: Open / Available | K38: 6:00-6:50 | M38: Open / Available | N38: 6:00-6:50 | P38: Open / Available
B39: 7:00-7:50 | D39: Open / Available | E39: 7:00-7:50 | G39: Open / Available | H39: 7:00-7:50 | J39: Open / Available | K39: 7:00-7:50 | M39: Open / Available | N39: 7:00-7:50 | P39: Open / Available
B40: 8:00-8:50 | D40: Open / Available | E40: 8:00-8:50 | G40: Open / Available | H40: 8:00-8:50 | J40: Open / Available | K40: 8:00-8:50 | M40: Open / Available | N40: 8:00-8:50 | P40: Open / Available
B41: 9:00-9:50 | D41: Open / Available | E41: 9:00-9:50 | G41: Open / Available | H41: 9:00-9:50 | J41: Open / Available | K41: 9:00-9:50 | M41: Open / Available | N41: 9:00-9:50 | P41: Open / Available
B42: 10:00-10:50 | D42: Open / Available | E42: 10:00-10:50 | G42: Open / Available | H42: 10:00-10:50 | J42: Open / Available | K42: 10:00-10:50 | M42: Open / Available | N42: 10:00-10:50 | P42: Open / Available

Sheet Weekend_Template
B1: TAMHA WEEKEND ICE SCHEDULE
B2: Weekend: Saturday & Sunday
B4: VENUE: TRURO STADIUM
B5: Saturday | E5: Sunday
B6: Time | C6: Team / User | D6: Status | E6: Time | F6: Team / User | G6: Status
B7: 8:00-8:50 | D7: Open / Available | E7: 8:00-8:50 | G7: Open / Available
B8: 9:00-9:50 | D8: Open / Available | E8: 9:00-9:50 | G8: Open / Available
B9: 10:00-10:50 | D9: Open / Available | E9: 10:00-10:50 | G9: Open / Available
B10: 11:00-11:50 | D10: Open / Available | E10: 11:00-11:50 | G10: Open / Available
B11: 12:00-12:50 | D11: Open / Available | E11: 12:00-12:50 | G11: Open / Available
B12: 13:00-13:50 | D12: Open / Available | E12: 13:00-13:50 | G12: Open / Available
B13: 14:00-14:50 | D13: Open / Available | E13: 14:00-14:50 | G13: Open / Available
B14: 15:00-15:50 | D14: Open / Available | E14: 15:00-15:50 | G14: Open / Available
B16: VENUE: RECC
B17: Saturday | E17: Sunday
B18: Time | C18: Team / User | D18: Status | E18: Time | F18: Team / User | G18: Status
B19: 8:00-8:50 | D19: Open / Available | E19: 8:00-8:50 | G19: Open / Available
B20: 9:00-9:50 | D20: Open / Available | E20: 9:00-9:50 | G20: Open / Available
B21: 10:00-10:50 | D21: Open / Available | E21: 10:00-10:50 | G21: Open / Available
B22: 11:00-11:50 | D22: Open / Available | E22: 11:00-11:50 | G22: Open / Available
B23: 12:00-12:50 | D23: Open / Available | E23: 12:00-12:50 | G23: Open / Available
B24: 13:00-13:50 | D24: Open / Available | E24: 13:00-13:50 | G24: Open / Available
B25: 14:00-14:50 | D25: Open / Available | E25: 14:00-14:50 | G25: Open / Available
B26: 15:00-15:50 | D26: Open / Available | E26: 15:00-15:50 | G26: Open / Available
B28: VENUE: DEUVILLES
B29: Saturday | E29: Sunday
B30: Time | C30: Team / User | D30: Status | E30: Time | F30: Team / User | G30: Status
B31: 8:00-8:50 | D31: Open / Available | E31: 8:00-8:50 | G31: Open / Available
B32: 9:00-9:50 | D32: Open / Available | E32: 9:00-9:50 | G32: Open / Available
B33: 10:00-10:50 | D33: Open / Available | E33: 10:00-10:50 | G33: Open / Available
B34: 11:00-11:50 | D34: Open / Available | E34: 11:00-11:50 | G34: Open / Available
B35: 12:00-12:50 | D35: Open / Available | E35: 12:00-12:50 | G35: Open / Available
B36: 13:00-13:50 | D36: Open / Available | E36: 13:00-13:50 | G36: Open / Available
B37: 14:00-14:50 | D37: Open / Available | E37: 14:00-14:50 | G37: Open / Available
B38: 15:00-15:50 | D38: Open / Available | E38: 15:00-15:50 | G38: Open / Available
B40: VENUE: DEBERT ARENA
B41: Saturday | E41: Sunday
B42: Time | C42: Team / User | D42: Status | E42: Time | F42: Team / User | G42: Status
B43: 8:00-8:50 | D43: Open / Available | E43: 8:00-8:50 | G43: Open / Available
B44: 9:00-9:50 | D44: Open / Available | E44: 9:00-9:50 | G44: Open / Available
...

Sheet Ice_Dashboard
B1: TAMHA ICE ALLOCATION & STATUS DASHBOARD
B2: Automatic aggregation of ice usage by status and team.
B4: Status Category | C4: Weekday Slots | D4: Weekend Slots | E4: Total Slots
B5: Open / Available | C5: =COUNTIF(Weekday_Template!$D$4:$P$50, "Open / Available") | D5: =COUNTIF(Weekend_Template!$D$4:$G$60, "Open / Available") | E5: =SUM(C5:D5)
B6: Booked: Practice | C6: =COUNTIF(Weekday_Template!$D$4:$P$50, "Booked: Practice") | D6: =COUNTIF(Weekend_Template!$D$4:$G$60, "Booked: Practice") | E6: =SUM(C6:D6)
B7: Booked: Home Game | C7: =COUNTIF(Weekday_Template!$D$4:$P$50, "Booked: Home Game") | D7: =COUNTIF(Weekend_Template!$D$4:$G$60, "Booked: Home Game") | E7: =SUM(C7:D7)
B8: Tentative Hold | C8: =COUNTIF(Weekday_Template!$D$4:$P$50, "Tentative Hold") | D8: =COUNTIF(Weekend_Template!$D$4:$G$60, "Tentative Hold") | E8: =SUM(C8:D8)
B9: Released / Dead Ice | C9: =COUNTIF(Weekday_Template!$D$4:$P$50, "Released / Dead Ice") | D9: =COUNTIF(Weekend_Template!$D$4:$G$60, "Released / Dead Ice") | E9: =SUM(C9:D9)
B10: TAMHA Development | C10: =COUNTIF(Weekday_Template!$D$4:$P$50, "TAMHA Development") | D10: =COUNTIF(Weekend_Template!$D$4:$G$60, "TAMHA Development") | E10: =SUM(C10:D10)
B11: Arena Conflict | C11: =COUNTIF(Weekday_Template!$D$4:$P$50, "Arena Conflict") | D11: =COUNTIF(Weekend_Template!$D$4:$G$60, "Arena Conflict") | E11: =SUM(C11:D11)
B15: Team / User | C15: Division | D15: Weekday Slots | E15: Weekend Slots | F15: Total Slots
B16: U7 - Group 4 | C16: U7 | D16: =COUNTIF(Weekday_Template!$C$4:$O$50, "U7 - Group 4") | E16: =COUNTIF(Weekend_Template!$C$4:$F$60, "U7 - Group 4") | F16: =SUM(D16:E16)
B17: U7 - 5 Blue | C17: U7 | D17: =COUNTIF(Weekday_Template!$C$4:$O$50, "U7 - 5 Blue") | E17: =COUNTIF(Weekend_Template!$C$4:$F$60, "U7 - 5 Blue") | F17: =SUM(D17:E17)
B18: U7 - 5 Orange | C18: U7 | D18: =COUNTIF(Weekday_Template!$C$4:$O$50, "U7 - 5 Orange") | E18: =COUNTIF(Weekend_Template!$C$4:$F$60, "U7 - 5 Orange") | F18: =SUM(D18:E18)
B19: U7 - Group 6 | C19: U7 | D19: =COUNTIF(Weekday_Template!$C$4:$O$50, "U7 - Group 6") | E19: =COUNTIF(Weekend_Template!$C$4:$F$60, "U7 - Group 6") | F19: =SUM(D19:E19)
B20: U9 - Intermediate | C20: U9 | D20: =COUNTIF(Weekday_Template!$C$4:$O$50, "U9 - Intermediate") | E20: =COUNTIF(Weekend_Template!$C$4:$F$60, "U9 - Intermediate") | F20: =SUM(D20:E20)
B21: U9 - Advanced | C21: U9 | D21: =COUNTIF(Weekday_Template!$C$4:$O$50, "U9 - Advanced") | E21: =COUNTIF(Weekend_Template!$C$4:$F$60, "U9 - Advanced") | F21: =SUM(D21:E21)
B22: U9 - Jayasinghe | C22: U9 | D22: =COUNTIF(Weekday_Template!$C$4:$O$50, "U9 - Jayasinghe") | E22: =COUNTIF(Weekend_Template!$C$4:$F$60, "U9 - Jayasinghe") | F22: =SUM(D22:E22)
B23: U9 - John | C23: U9 | D23: =COUNTIF(Weekday_Template!$C$4:$O$50, "U9 - John") | E23: =COUNTIF(Weekend_Template!$C$4:$F$60, "U9 - John") | F23: =SUM(D23:E23)
B24: U11 AA | C24: U11 | D24: =COUNTIF(Weekday_Template!$C$4:$O$50, "U11 AA") | E24: =COUNTIF(Weekend_Template!$C$4:$F$60, "U11 AA") | F24: =SUM(D24:E24)
B25: U11 A | C25: U11 | D25: =COUNTIF(Weekday_Template!$C$4:$O$50, "U11 A") | E25: =COUNTIF(Weekend_Template!$C$4:$F$60, "U11 A") | F25: =SUM(D25:E25)
B26: U11 B | C26: U11 | D26: =COUNTIF(Weekday_Template!$C$4:$O$50, "U11 B") | E26: =COUNTIF(Weekend_Template!$C$4:$F$60, "U11 B") | F26: =SUM(D26:E26)
B27: U11 C - Bernard | C27: U11 | D27: =COUNTIF(Weekday_Template!$C$4:$O$50, "U11 C - Bernard") | E27: =COUNTIF(Weekend_Template!$C$4:$F$60, "U11 C - Bernard") | F27: =SUM(D27:E27)
B28: U11 C - Simms | C28: U11 | D28: =COUNTIF(Weekday_Template!$C$4:$O$50, "U11 C - Simms") | E28: =COUNTIF(Weekend_Template!$C$4:$F$60, "U11 C - Simms") | F28: =SUM(D28:E28)
B29: U13 AAA | C29: U13 | D29: =COUNTIF(Weekday_Template!$C$4:$O$50, "U13 AAA") | E29: =COUNTIF(Weekend_Template!$C$4:$F$60, "U13 AAA") | F29: =SUM(D29:E29)
B30: U13 AA | C30: U13 | D30: =COUNTIF(Weekday_Template!$C$4:$O$50, "U13 AA") | E30: =COUNTIF(Weekend_Template!$C$4:$F$60, "U13 AA") | F30: =SUM(D30:E30)
B31: U13 A - Malone | C31: U13 | D31: =COUNTIF(Weekday_Template!$C$4:$O$50, "U13 A - Malone") | E31: =COUNTIF(Weekend_Template!$C$4:$F$60, "U13 A - Malone") | F31: =SUM(D31:E31)
B32: U13 B | C32: U13 | D32: =COUNTIF(Weekday_Template!$C$4:$O$50, "U13 B") | E32: =COUNTIF(Weekend_Template!$C$4:$F$60, "U13 B") | F32: =SUM(D32:E32)
B33: U13 C - Campbell | C33: U13 | D33: =COUNTIF(Weekday_Template!$C$4:$O$50, "U13 C - Campbell") | E33: =COUNTIF(Weekend_Template!$C$4:$F$60, "U13 C - Campbell") | F33: =SUM(D33:E33)
B34: U13 C - Cameron | C34: U13 | D34: =COUNTIF(Weekday_Template!$C$4:$O$50, "U13 C - Cameron") | E34: =COUNTIF(Weekend_Template!$C$4:$F$60, "U13 C - Cameron") | F34: =SUM(D34:E34)
B35: U15 AA | C35: U15 | D35: =COUNTIF(Weekday_Template!$C$4:$O$50, "U15 AA") | E35: =COUNTIF(Weekend_Template!$C$4:$F$60, "U15 AA") | F35: =SUM(D35:E35)
B36: U15 A | C36: U15 | D36: =COUNTIF(Weekday_Template!$C$4:$O$50, "U15 A") | E36: =COUNTIF(Weekend_Template!$C$4:$F$60, "U15 A") | F36: =SUM(D36:E36)
B37: U15 C - Bernard | C37: U15 | D37: =COUNTIF(Weekday_Template!$C$4:$O$50, "U15 C - Bernard") | E37: =COUNTIF(Weekend_Template!$C$4:$F$60, "U15 C - Bernard") | F37: =SUM(D37:E37)
B38: U15 C - Campbell | C38: U15 | D38: =COUNTIF(Weekday_Template!$C$4:$O$50, "U15 C - Campbell") | E38: =COUNTIF(Weekend_Template!$C$4:$F$60, "U15 C - Campbell") | F38: =SUM(D38:E38)
B39: U18 AA | C39: U18 | D39: =COUNTIF(Weekday_Template!$C$4:$O$50, "U18 AA") | E39: =COUNTIF(Weekend_Template!$C$4:$F$60, "U18 AA") | F39: =SUM(D39:E39)
B40: U18 A | C40: U18 | D40: =COUNTIF(Weekday_Template!$C$4:$O$50, "U18 A") | E40: =COUNTIF(Weekend_Template!$C$4:$F$60, "U18 A") | F40: =SUM(D40:E40)
B41: U18 C - Masters | C41: U18 | D41: =COUNTIF(Weekday_Template!$C$4:$O$50, "U18 C - Masters") | E41: =COUNTIF(Weekend_Template!$C$4:$F$60, "U18 C - Masters") | F41: =SUM(D41:E41)
B42: U18 C - Wood | C42: U18 | D42: =COUNTIF(Weekday_Template!$C$4:$O$50, "U18 C - Wood") | E42: =COUNTIF(Weekend_Template!$C$4:$F$60, "U18 C - Wood") | F42: =SUM(D42:E42)
B43: Dev - TAMHA Skills | C43: Assoc | D43: =COUNTIF(Weekday_Template!$C$4:$O$50, "Dev - TAMHA Skills") | E43: =COUNTIF(Weekend_Template!$C$4:$F$60, "Dev - TAMHA Skills") | F43: =SUM(D43:E43)
B44: Dev - Goalie Clinic | C44: Assoc | D44: =COUNTIF(Weekday_Template!$C$4:$O$50, "Dev - Goalie Clinic") | E44: =COUNTIF(Weekend_Template!$C$4:$F$60, "Dev - Goalie Clinic") | F44: =SUM(D44:E44)
...
