Workbook

Sheet Budget Summary
A1: TRURO AREA MINOR HOCKEY ASSOCIATION (TAMHA)
A2: Official Team Operating Budget & Financial Reporting Ledger (2026–2027 Season)
A4: Team Division & Name: | B4: [Enter Team Name - e.g., Truro Bearcats U13 A] | D4: Team Tier: | E4: Rep (AA / A / B) | F4: Roster Players: | G4: =IF(COUNTA('Roster & Fee Tracker'!B5:B25)>0, COUNTA('Roster & Fee Tracker'!B5:B25), 17) -> 17
A5: Head Coach: | B5: [Head Coach Full Name] | D5: Team Manager: | E5: [Team Manager Full Name] | F5: Team Treasurer: | G5: [Team Treasurer Full Name]
A6: Mosaik Account #: | B6: [Enter 9-Digit Account #] | D6: Reporting Stage: | E6: Preliminary Budget (Oct 30) | F6: Season Status: | G6: Active
A8: ℹ️ MANAGER INSTRUCTIONS & TAMHA FINANCIAL POLICY FRAMEWORK: 1. Do NOT manually type budget figures into this summary tab! All numbers roll up automatically from the detailed line items entered on the 'Income' and 'Expenses' tabs. Simply enter your team's budget line items on those two tabs. 2. Rep Teams vs. House (C-League): Rep fees are $9,500 total ($4,750 on Nov 30 & $4,750 on Jan 31; AAA is $11,500; House is $0). To avoid sticker shock, note that Rep fees comprehensively include: • Mandatory annual sweater/jersey replacement fund (previously billed as a separate $550 charge). • Hockey Nova Scotia (HNS) & Conference League scheduling and affiliation fees. • Official TAMHA Bearcats game socks (2 pairs per player: Home Crimson & Away White, supplied at equipment pickup). 3. Mandatory TAMHA Financial Policies: • Zero Deficit Rule: Teams are not permitted to project or operate at a deficit. Projected revenues must equal or exceed projected expenses. • Sponsorships vs. Fundraising: Corporate sponsorships are commercial advertising contributions (must issue official TAMHA commercial receipts, not charitable tax receipts). Fundraising proceeds (50/50, bottle drives) belong to the team/association; surplus fundraising cannot be paid out as personal cash profits to families. • Parent Contributions: All parent fee assessments (rep fee installments & cash calls) require a >75% majority vote approval by team families at the initial parent meeting. • Jersey Deposits Held in Trust: Mandatory $150 Rep / $50 House deposits must be held in trust (uncashed cheques dated May 15, 2027 or segregated balance) and refunded 100% upon jersey return in April. 4. Optional Tools: Both the 'Bank Rec' and 'Roster & Fee Tracker' tabs are optional team management tools and are NOT required for your official budget submission.
A12: 1.0 REVENUE SUMMARY (ROLLUP FROM INCOME SHEET)
A13: Revenue Category | B13: Projected ($) | C13: Actual YTD ($) | D13: Variance ($) | E13: % Achieved | F13: Status | G13: Notes / Verification
A14: 1.1 Corporate & Local Sponsorships | B14: =Income!E14 -> 2950 | C14: =Income!F14 -> 0 | D14: =C14-B14 -> -2950 | E14: =IF(B14>0, C14/B14, 0) -> 0 | F14: =IF(D14>=0,"On Target","Pending") -> Pending | G14: Team sponsors & banner ads
A15: 1.2 Team Fundraising Initiatives | B15: =Income!D23 -> 3800 | C15: =Income!E23 -> 0 | D15: =C15-B15 -> -3800 | E15: =IF(B15>0, C15/B15, 0) -> 0 | F15: =IF(D15>=0,"On Target","In Progress") -> In Progress | G15: Bottle drive, 50/50, draws
A16: 1.3 Parent Fee Contributions (Rep/Team Fees) | B16: =Income!D33 -> 11199.94 | C16: =Income!E33 -> 0 | D16: =C16-B16 -> -11199.94 | E16: =IF(B16>0, C16/B16, 0) -> 0 | F16: =IF(D16>=0,"Collected","Pending") -> Pending | G16: Per-player installments
A17: 1.4 Parent Jersey Deposits (Held in Trust) | B17: =Income!D41 -> 2550 | C17: =Income!E41 -> 0 | D17: =C17-B17 -> -2550 | E17: =IF(B17>0, C17/B17, 0) -> 0 | F17: =IF(D17>=0,"Collected","Pending") -> Pending | G17: Refunded at end of season
A18: 1.5 Bank Interest & Miscellaneous Revenue | B18: =Income!D47 -> 0 | C18: =Income!E47 -> 0 | D18: =C18-B18 -> 0 | E18: =IF(B18>0, C18/B18, 0) -> 0 | F18: "Balanced" | G18: Account interest / other
A21: TOTAL PROJECTED & ACTUAL REVENUE | B21: =SUM(B14:B18) -> 20499.94 | C21: =SUM(C14:C18) -> 0 | D21: =C21-B21 -> -20499.94 | E21: =IF(B21>0, C21/B21, 0) -> 0 | F21: =IF(D21>=0,"SURPLUS / ON TRACK","DEFICIT") -> DEFICIT | G21: Rolls up all 5 income categories
A24: 2.0 EXPENSE SUMMARY (ROLLUP FROM EXPENSES SHEET)
A25: Expense Category | B25: Projected ($) | C25: Actual YTD ($) | D25: Variance ($) | E25: % Spent | F25: Status | G25: Notes / Verification
A26: 2.1 TAMHA Association & League Fees | B26: =Expenses!E11 -> 9500 | C26: =Expenses!F11 -> 0 | D26: =B26-C26 -> 9500 | E26: =IF(B26>0, C26/B26, 0) -> 0 | F26: =IF(C26<=B26,"On Budget","Over") -> On Budget | G26: Rep fees ($9,500 total; includes jersey fund)
A27: 2.2 Tournaments & Jamborees Entry Fees | B27: =Expenses!E22 -> 3800 | C27: =Expenses!F22 -> 0 | D27: =B27-C27 -> 3800 | E27: =IF(B27>0, C27/B27, 0) -> 0 | F27: =IF(C27<=B27,"On Budget","Over") -> On Budget | G27: Tournament registrations
A28: 2.3 Extra Practice Ice & Game Officials | B28: =Expenses!E32 -> 1746 | C28: =Expenses!F32 -> 0 | D28: =B28-C28 -> 1746 | E28: =IF(B28>0, C28/B28, 0) -> 0 | F28: =IF(C28<=B28,"On Budget","Over") -> On Budget | G28: Ice rental, ref & timekeeper fees
A29: 2.4 Team Apparel, Items & Equipment | B29: =Expenses!E43 -> 1220 | C29: =Expenses!F43 -> 0 | D29: =B29-C29 -> 1220 | E29: =IF(B29>0, C29/B29, 0) -> 0 | F29: =IF(C29<=B29,"On Budget","Over") -> On Budget | G29: Practice jerseys, banner, name bars, socks
A30: 2.5 Team Events & Player Activities | B30: =Expenses!E51 -> 1350 | C30: =Expenses!F51 -> 0 | D30: =B30-C30 -> 1350 | E30: =IF(B30>0, C30/B30, 0) -> 0 | F30: =IF(C30<=B30,"On Budget","Over") -> On Budget | G30: Holiday party, year-end banquet, gifts
A31: 2.6 Operating Costs, Banking & Contingency | B31: =Expenses!E59 -> 333.94 | C31: =Expenses!F59 -> 0 | D31: =B31-C31 -> 333.94 | E31: =IF(B31>0, C31/B31, 0) -> 0 | F31: =IF(C31<=B31,"On Budget","Over") -> On Budget | G31: Mosaik fees, cheques, contingency buffer
A32: 2.7 Return of Parent Jersey Deposits | B32: =Expenses!E65 -> 2550 | C32: =Expenses!F65 -> 0 | D32: =B32-C32 -> 2550 | E32: =IF(B32>0, C32/B32, 0) -> 0 | F32: =IF(C32<=B32,"Pending EOY","Refunded") -> Pending EOY | G32: Refunded to parents upon jersey return
A36: TOTAL PROJECTED & ACTUAL EXPENSES | B36: =SUM(B26:B32) -> 20499.94 | C36: =SUM(C26:C32) -> 0 | D36: =B36-C36 -> 20499.94 | E36: =IF(B36>0, C36/B36, 0) -> 0 | F36: =IF(D36>=0,"UNDER BUDGET","OVER BUDGET") -> UNDER BUDGET | G36: Rolls up all 7 expense categories
A38: 3.0 NET POSITION & PER-PLAYER BREAKDOWN
A39: Net Team Cash Position (Revenue - Expenses) | B39: =B21-B36 -> 0 | C39: =C21-C36 -> 0 | D39: =C39-B39 -> 0 | F39: =IF(B39>=0,"BALANCED / SURPLUS","DEFICIT") -> BALANCED / SURPLUS | G39: Target is balanced ($0.00)
A40: Gross Team Operating Cost Per Player | B40: =B36/$G$4 -> 1205.8788 | C40: =C36/$G$4 -> 0 | D40: =B40-C40 -> 1205.8788 | G40: Total team cost divided by roster count
A41: Team Fundraising & Sponsorship Raised Per Player | B41: =(B14+B15)/$G$4 -> 397.05882 | C41: =(C14+C15)/$G$4 -> 0 | D41: =C41-B41 -> -397.05882 | G41: Subsidized through team sponsors & events
A42: Net Parent Out-of-Pocket Cost Per Player | B42: =B16/$G$4 -> 658.82 | C42: =C16/$G$4 -> 0 | D42: =B42-C42 -> 658.82 | G42: Actual parent fee required per family
A45: 4.0 EXECUTIVE GOVERNANCE & SUBMISSION CHECKLIST
A46: Milestone 1: Preliminary Budget presented to Parents & approved (>75% majority vote) | E46: October 30, 2026 | F46: Manager & Treasurer | G46: Approved
A47: Milestone 2: Preliminary Budget submitted to VP Finance (vpfinance@trurominorhockey.ca) | E47: October 30, 2026 | F47: VP Finance (Joe Zappia) | G47: Submitted
A48: Milestone 3: Mid-Season Financial Statement shared with Parent Group | E48: December 31, 2026 | F48: Parent Group | G48: Scheduled
A49: Milestone 4: Interim Financial Statement submitted to VP Finance | E49: January 15, 2027 | F49: VP Finance (Joe Zappia) | G49: Scheduled
A50: Milestone 5: Final Year-End Budget & Reconciliation submitted to VP Finance | E50: March 31, 2027 | F50: VP Finance (Joe Zappia) | G50: Scheduled
A51: Milestone 6: Final Financial Statement & Jersey Deposit refunds distributed to Parents | E51: April 15, 2027 | F51: Parent Group | G51: Scheduled

Sheet Income
A1: TAMHA TEAM REVENUE & INCOME TRACKER
A2: Detail Ledger: Sponsorships, Fundraising, Parent Contributions & Jersey Deposits
A4: 1.0 SPONSORSHIPS & LOCAL BUSINESS ADVERTISING (TAMHA Policy: Commercial Advertising Receipts Issued — Not Charitable Tax Deductions)
A5: Sponsor / Business Name | B5: Sponsorship Level | C5: Contact Person | D5: Payment Method | E5: Projected ($) | F5: Actual Received ($) | G5: Receipt Issued?
A6: [Major Team Sponsor - e.g. Local Business] | B6: Major ($1,000+) | C6: [Contact Name] | D6: [Cheque / E-transfer] | E6: 1000 | F6: 0 | G6: Pending
A7: [Gold Banner Sponsor 1] | B7: Gold ($500) | C7: [Contact Name] | D7: [Cheque / E-transfer] | E7: 500 | F7: 0 | G7: Pending
A8: [Gold Banner Sponsor 2] | B8: Gold ($500) | C8: [Contact Name] | D8: [Cheque / E-transfer] | E8: 500 | F8: 0 | G8: Pending
A9: [Silver Banner Sponsor 1] | B9: Silver ($250) | C9: [Contact Name] | D9: [Cheque / E-transfer] | E9: 250 | F9: 0 | G9: Pending
A10: [Silver Banner Sponsor 2] | B10: Silver ($250) | C10: [Contact Name] | D10: [Cheque / E-transfer] | E10: 250 | F10: 0 | G10: Pending
A11: [Silver Banner Sponsor 3] | B11: Silver ($250) | C11: [Contact Name] | D11: [Cheque / E-transfer] | E11: 250 | F11: 0 | G11: Pending
A12: [Bronze Banner Sponsor 1] | B12: Bronze ($100) | C12: [Contact Name] | D12: [Cheque / E-transfer] | E12: 100 | F12: 0 | G12: Pending
A13: [Bronze Banner Sponsor 2] | B13: Bronze ($100) | C13: [Contact Name] | D13: [Cheque / E-transfer] | E13: 100 | F13: 0 | G13: Pending
A14: SUBTOTAL: SPONSORSHIPS | E14: =SUM(E6:E13) -> 2950 | F14: =SUM(F6:F13) -> 0
A16: 2.0 TEAM FUNDRAISING INITIATIVES (TAMHA Policy: Team/Association Property — Surplus Cannot Be Distributed as Cash Payouts to Families)
A17: Fundraiser Name / Description | B17: Event Date | C17: Lead Coordinator | D17: Projected ($) | E17: Actual Net ($) | F17: Variance ($) | G17: Status / Notes
A18: [Team Bottle Drive - Fall] | B18: [Oct 2026] | C18: [Parent Volunteer] | D18: 1000 | E18: 0 | F18: =E18-D18 -> -1000 | G18: Planned
A19: [50/50 Raffle - e.g. Pot O' Gold] | B19: [Nov 2026] | C19: [Treasurer] | D19: 1500 | E19: 0 | F19: =E19-D19 -> -1500 | G19: Planned
A20: [Ticket Draw / Grand In Your Hand] | B20: [Dec 2026] | C20: [Manager] | D20: 800 | E20: 0 | F20: =E20-D20 -> -800 | G20: Planned
A21: [Square Board / Silent Auction] | B21: [Feb 2027] | C21: [Parent Committee] | D21: 500 | E21: 0 | F21: =E21-D21 -> -500 | G21: Planned
A22: [Optional Fundraiser 5] | B22: [TBD] | C22: [Volunteer] | D22: 0 | E22: 0 | F22: =E22-D22 -> 0 | G22: Optional
A23: SUBTOTAL: FUNDRAISING | D23: =SUM(D18:D22) -> 3800 | E23: =SUM(E18:E22) -> 0 | F23: =E23-D23 -> -3800
A25: 3.0 PARENT CONTRIBUTIONS & TEAM FEES (TAMHA Policy: Mandatory >75% Majority Parent Vote Approval Required)
A26: Fee Description | B26: Per Player ($) | C26: Roster Size | D26: Projected Total ($) | E26: Actual Collected ($) | F26: Variance ($) | G26: Due Date / Installment
A27: Rep Fee Contribution - Installment 1 (Nov) | B27: =ROUND(Expenses!E6/'Budget Summary'!$G$4, 2) -> 279.41 | C27: ='Budget Summary'!$G$4 -> 17 | D27: =B27*C27 -> 4749.97 | E27: 0 | F27: =E27-D27 -> -4749.97 | G27: November 15, 2026
A28: Rep Fee Contribution - Installment 2 (Jan) | B28: =ROUND(Expenses!E7/'Budget Summary'!$G$4, 2) -> 279.41 | C28: ='Budget Summary'!$G$4 -> 17 | D28: =B28*C28 -> 4749.97 | E28: 0 | F28: =E28-D28 -> -4749.97 | G28: January 31, 2027
A29: Team Operational Cash Call (Apparel / Extras) | B29: 100 | C29: ='Budget Summary'!$G$4 -> 17 | D29: =B29*C29 -> 1700 | E29: 0 | F29: =E29-D29 -> -1700 | G29: December 1, 2026
A30: Optional Tournament / Extra Ice Cash Call | B30: 0 | C30: ='Budget Summary'!$G$4 -> 17 | D30: =B30*C30 -> 0 | E30: 0 | F30: =E30-D30 -> 0 | G30: As needed
A33: SUBTOTAL: PARENT CONTRIBUTIONS | D33: =SUM(D27:D30) -> 11199.94 | E33: =SUM(E27:E30) -> 0 | F33: =E33-D33 -> -11199.94
A35: 4.0 PARENT JERSEY DEPOSITS (HELD IN TRUST — Strict Policy: Liability Funds Only; Never Spent on Operations; 100% Refundable)
A36: Deposit Type | B36: Deposit / Player | C36: Roster Size | D36: Projected Total ($) | E36: Actual Collected ($) | F36: Method | G36: Policy Rule
A37: Rep Team Jersey Deposit ($150 / player) | B37: 150 | C37: ='Budget Summary'!$G$4 -> 17 | D37: =B37*C37 -> 2550 | E37: 0 | F37: Post-dated cheque / E-transfer | G37: Mandatory $150 Rep / $50 House
A38: Uncashed Cheques Held in Safe Keeping | B38: 0 | C38: ='Budget Summary'!$G$4 -> 17 | D38: 0 | E38: 0 | F38: Cheques dated May 15, 2027 | G38: Returned or destroyed upon jersey return
A41: SUBTOTAL: JERSEY DEPOSITS HELD | D41: =D37+D38 -> 2550 | E41: =E37+E38 -> 0 | F41: =E41-D41 -> -2550
A43: 5.0 BANK INTEREST & MISCELLANEOUS REVENUE
A44: Mosaik Credit Union Account Interest | D44: 0 | E44: 0 | G44: Credit Union operating account interest
A47: SUBTOTAL: MISCELLANEOUS REVENUE | D47: =D44 -> 0 | E47: =E44 -> 0 | F47: =E47-D47 -> 0
A49: TOTAL TEAM REVENUE (ALL 5 CATEGORIES) | D49: =E14+D23+D33+D41+D47 -> 20499.94 | E49: =F14+E23+E33+E41+E47 -> 0 | F49: =E49-D49 -> -20499.94 | G49: =IF(F49>=0,"Surplus / Target Met","Pending") -> Pending

Sheet Expenses
A1: TAMHA TEAM EXPENSE & OPERATING COST LEDGER
A2: Detail Ledger: Association Fees, Tournaments, Ice/Officials, Apparel, Activities & Banking
A4: 1.0 TAMHA ASSOCIATION & LEAGUE FEES
A5: Fee Description | B5: Payment Due Date | C5: Payment Method | D5: Category | E5: Projected ($) | F5: Actual Paid ($) | G5: Notes / Invoices
A6: TAMHA Rep Fees - Installment 1 (50%) | B6: 46356 | C6: Cheque / E-transfer | D6: Mandatory | E6: 4750 | F6: 0 | G6: Official association invoice (includes jersey fund)
A7: TAMHA Rep Fees - Installment 2 (50%) | B7: Jan 31, 2027 | C7: Cheque / E-transfer | D7: Mandatory | E7: 4750 | F7: 0 | G7: Official association invoice (includes jersey fund)
A8: TAMHA Mandatory Sweater / Jersey Fund | B8: 46356 | C8: Included in Rep Fee | D8: Included | E8: 0 | F8: 0 | G8: Included in $9,500 Rep Fee total (no separate $550 payment required)
A9: HNS & Conference League Scheduling Fees | B9: 46327 | C9: Included in Rep Fee | D9: Included | E9: 0 | F9: 0 | G9: Included in $9,500 Rep Fee total (covered under association league registration)
A10: League / Regional Playoff Assessment Fees | B10: 46433 | C10: Included in Rep Fee | D10: Included | E10: 0 | F10: 0 | G10: Included in $9,500 Rep Fee total / covered by association
A11: SUBTOTAL: TAMHA & LEAGUE FEES | E11: =SUM(E6:E10) -> 9500 | F11: =SUM(F6:F10) -> 0 | G11: =E11-F11 -> 9500
A16: 2.0 TOURNAMENTS & JAMBOREES
A17: Tournament Name | B17: Tournament Dates | C17: Location | D17: Permit Status | E17: Projected ($) | F17: Actual Paid ($) | G17: Notes / Travel Permits
A18: Tournament 1: [Early Bird / Pre-Season Event] | B18: Nov 2026 | C18: [Host Town, NS] | D18: Sanctioned | E18: 850 | F18: 0 | G18: Early season tournament
A19: Tournament 2: [Holiday / Winter Invitational] | B19: Dec 2026 | C19: [Host Town, NS] | D19: Sanctioned | E19: 900 | F19: 0 | G19: Holiday event
A20: Tournament 3: [SEDMHA / March Tournament] | B20: Mar 2027 | C20: Halifax / Dartmouth | D20: Sanctioned | E20: 1200 | F20: 0 | G20: Major spring tournament
A21: Tournament 4: [Away / Travel Tournament] | B21: Mar 2027 | C21: [PEI / NB / Local] | D21: Sanctioned | E21: 850 | F21: 0 | G21: Travel permit required
A22: SUBTOTAL: TOURNAMENTS | E22: =SUM(E18:E21) -> 3800 | F22: =SUM(F18:F21) -> 0 | G22: =E22-F22 -> 3800
A26: 3.0 EXTRA PRACTICE ICE & GAME OFFICIALS
A27: Ice / Official Item | B27: Rate & Quantity | C27: Facility / Venue | D27: Event Type | E27: Projected ($) | F27: Actual Paid ($) | G27: Notes / Invoices
A28: Additional Practice Ice (Full Ice) | B28: 6 Hours @ $165/hr | C28: Local Rink / RECC | D28: Pre-Season / Practice | E28: 990 | F28: 0 | G28: Extra team development ice
A29: Exhibition Game Ice Rental | B29: 2 Games @ $258/game | C29: Home Rink | D29: Exhibition | E29: 516 | F29: 0 | G29: Home exhibition game slots
A30: Referee & Linesmen Official Fees | B30: 2 Games @ $90/game | C30: HNS Certified Officials | D30: Exhibition | E30: 180 | F30: 0 | G30: Cash payout for officials
A31: Timekeeper & Scorekeeper Fees | B31: 2 Games @ $30/game | C31: Timekeeper Association | D31: Exhibition | E31: 60 | F31: 0 | G31: Clock / game sheet operator
A32: SUBTOTAL: EXTRA ICE & OFFICIALS | E32: =SUM(E28:E31) -> 1746 | F32: =SUM(F28:F31) -> 0 | G32: =E32-F32 -> 1746
A35: 4.0 TEAM APPAREL, GEAR & ITEMS
A36: Item Description | B36: Quantity & Pricing | C36: Vendor / Supplier | D36: Usage | E36: Projected ($) | F36: Actual Paid ($) | G36: Notes / Receipts
A37: Practice Jerseys (Forward & Defence Colours) | B37: 2 Team Sets (Dark / Light) | C37: Apparel Vendor | D37: Team Property | E37: 550 | F37: 0 | G37: Kept by team / passed down (used for practice drills & intra-squad scrimmage)
A38: Sponsor Display Banner (Printed) | B38: Arena Display Banner | C38: Local Print Shop | D38: Sponsor Value | E38: 200 | F38: 0 | G38: Displays sponsor logos at arena
A39: Sponsor Bars / Player Name Bars & Sewing | B39: 17 Players | C39: Sewing Specialist | D39: Player Apparel | E39: 250 | F39: 0 | G39: Custom name bars sewn on game jerseys
A40: Team Game Socks (Home & Away - 2 Pairs/Player) | B40: 17 Players @ 2 pairs (Supplied by TAMHA) | C40: TAMHA Equipment Manager | D40: Included in Rep Fee | E40: 0 | F40: 0 | G40: Included in $9,500 Rep Fee (official Bearcats crimson & white socks supplied at equipment pickup)
A41: Team First Aid Kit & Safety Supplies | B41: Full Season Kit | C41: Local Pharmacy / Sport | D41: Safety Person | E41: 100 | F41: 0 | G41: Required for every team bench
A42: Practice Pucks, Cones, Whiteboard | B42: Puck bag & coaching items | C42: Sporting Goods | D42: Coaching Staff | E42: 120 | F42: 0 | G42: Team practice equipment
A43: SUBTOTAL: APPAREL & TEAM ITEMS | E43: =SUM(E37:E42) -> 1220 | F43: =SUM(F37:F42) -> 0 | G43: =E43-F43 -> 1220
A45: 5.0 TEAM ACTIVITIES & PLAYER EVENTS
A46: Activity / Event Name | B46: Date / Frequency | C46: Location / Details | D46: Participants | E46: Projected ($) | F46: Actual Paid ($) | G46: Notes / Receipts
A47: Holiday / Christmas Family Team Party | B47: Dec 2026 | C47: Local Venue / Rink | D47: All Families | E47: 450 | F47: 0 | G47: Food, activities, gifts
A48: Year-End Team Party & Banquet | B48: Apr 2027 | C48: Local Restaurant / Hall | D48: All Families | E48: 500 | F48: 0 | G48: Awards, meal, celebration
A49: Team Away Game Snacks & Nutrition | B49: Full Season | C49: Grocery / Wholesale | D49: Player Health | E49: 250 | F49: 0 | G49: Fruit, granola bars, electrolytes
A50: Coaching Staff Appreciation Gifts | B50: Head Coach & Bench Staff | C50: Local Retailer | D50: Volunteer Recognition | E50: 150 | F50: 0 | G50: End-of-year volunteer gifts
A51: SUBTOTAL: TEAM ACTIVITIES | E51: =SUM(E47:E50) -> 1350 | F51: =SUM(F47:F50) -> 0 | G51: =E51-F51 -> 1350
...

Sheet Bank Rec
A1: MOSAIK CREDIT UNION - MONTHLY BANK RECONCILIATION
A2: Reconciles Bank Statement Balance Against Team Budget Cash Position
A3: ℹ️ OPTIONAL TOOL: This reconciliation ledger is provided for team convenience and is NOT required for your official TAMHA budget submission.
A4: Team Name: | B4: ='Budget Summary'!$B$4 -> [Enter Team Name - e.g., Truro Bearcats U13 A] | D4: Mosaik Account #: | E4: ='Budget Summary'!$B$6 -> [Enter 9-Digit Account #]
A5: Statement Date: | B5: [Enter Statement Date - e.g. Oct 31, 2026] | D5: Reconciled By: | E5: ='Budget Summary'!$G$5 -> [Team Treasurer Full Name]
A7: 1. Ending Balance per Mosaik Bank Statement | E7: 0
A9: 2. ADD: Outstanding Deposits (Recorded in ledger, not yet cleared on bank statement)
A10: Deposit Description | B10: Date Received | C10: Payer / Source | D10: Payment Method | E10: Amount ($) | F10: Notes
A11: [Deposit 1 Description] | B11: [Date] | C11: [Source / Payer] | D11: [Method] | E11: 0 | F11: [Pending clearance]
A12: [Deposit 2 Description] | B12: [Date] | C12: [Source / Payer] | D12: [Method] | E12: 0 | F12: [Pending clearance]
A13: [Deposit 3 Description] | B13: [Date] | C13: [Source / Payer] | D13: [Method] | E13: 0 | F13: [Pending clearance]
E14: 0
E15: 0
A16: TOTAL OUTSTANDING DEPOSITS | E16: =SUM(E11:E15) -> 0
A18: 3. LESS: Outstanding Withdrawals & Cheques (Issued in ledger, not yet cashed)
A19: Cheque # / Transaction | B19: Date Issued | C19: Payee / Vendor | D19: Description | E19: Amount ($) | F19: Status
A20: [Cheque #101] | B20: [Date] | C20: [Payee / Vendor] | D20: [Description / Purpose] | E20: 0 | F20: Issued, not yet cashed
A21: [Cheque #102] | B21: [Date] | C21: [Payee / Vendor] | D21: [Description / Purpose] | E21: 0 | F21: Issued, not yet cashed
A22: [Cheque #103] | B22: [Date] | C22: [Payee / Vendor] | D22: [Description / Purpose] | E22: 0 | F22: Issued, not yet cashed
E23: 0
E24: 0
E25: 0
A26: TOTAL OUTSTANDING WITHDRAWALS | E26: =SUM(E20:E25) -> 0
A28: 4. ADJUSTED BANK BALANCE (Bank Balance + Deposits - Withdrawals) | E28: =E7+E16-E26 -> 0
A29: 5. BOOK BALANCE PER TEAM BUDGET (Actual Revenue YTD - Actual Expenses YTD) | E29: ='Budget Summary'!C21-'Budget Summary'!C36 -> 0
A30: 6. UNRECONCILED VARIANCE / DIFFERENCE (Must equal $0.00) | E30: =E28-E29 -> 0 | F30: =IF(ROUND(E30,2)=0,"✅ BALANCED - PERFECT RECONCILIATION","⚠️ OUT OF BALANCE") -> ✅ BALANCED - PERFECT RECONCILIATION

Sheet Roster & Fee Tracker
A1: INDIVIDUAL PLAYER FEE & JERSEY DEPOSIT TRACKING LEDGER
A2: Tracks Parent Payments, Jersey Deposit Cheques, Fundraising Quotas & Refund Approvals
A3: ℹ️ OPTIONAL TOOL: This roster and fee ledger is provided for team tracking and is NOT required for your official TAMHA budget submission.
A4: Jersey # | B4: Player Legal Name | C4: Parent / Guardian Contact | D4: Parent Email | E4: Jersey Deposit ($150) | F4: Rep Fee Installment 1 | G4: Rep Fee Installment 2 | H4: Team Fee / Cash Call ($100) | I4: Total Paid ($) | J4: Balance Due ($) | K4: Jersey Returned & Deposit Cleared?
A5: #01 | B5: [Player 01 Legal Name] | C5: [Parent / Guardian of Player 01] | D5: [parent01@example.com] | E5: 0 | F5: 0 | G5: 0 | H5: 0 | I5: =SUM(E5:H5) -> 0 | J5: =IF(B5="","",(Income!$B$37+Income!$B$27+Income!$B$28+Income!$B$29)-I5) -> 808.82 | K5: Pending
A6: #02 | B6: [Player 02 Legal Name] | C6: [Parent / Guardian of Player 02] | D6: [parent02@example.com] | E6: 0 | F6: 0 | G6: 0 | H6: 0 | I6: =SUM(E6:H6) -> 0 | J6: =IF(B6="","",(Income!$B$37+Income!$B$27+Income!$B$28+Income!$B$29)-I6) -> 808.82 | K6: Pending
A7: #03 | B7: [Player 03 Legal Name] | C7: [Parent / Guardian of Player 03] | D7: [parent03@example.com] | E7: 0 | F7: 0 | G7: 0 | H7: 0 | I7: =SUM(E7:H7) -> 0 | J7: =IF(B7="","",(Income!$B$37+Income!$B$27+Income!$B$28+Income!$B$29)-I7) -> 808.82 | K7: Pending
A8: #04 | B8: [Player 04 Legal Name] | C8: [Parent / Guardian of Player 04] | D8: [parent04@example.com] | E8: 0 | F8: 0 | G8: 0 | H8: 0 | I8: =SUM(E8:H8) -> 0 | J8: =IF(B8="","",(Income!$B$37+Income!$B$27+Income!$B$28+Income!$B$29)-I8) -> 808.82 | K8: Pending
A9: #05 | B9: [Player 05 Legal Name] | C9: [Parent / Guardian of Player 05] | D9: [parent05@example.com] | E9: 0 | F9: 0 | G9: 0 | H9: 0 | I9: =SUM(E9:H9) -> 0 | J9: =IF(B9="","",(Income!$B$37+Income!$B$27+Income!$B$28+Income!$B$29)-I9) -> 808.82 | K9: Pending
A10: #06 | B10: [Player 06 Legal Name] | C10: [Parent / Guardian of Player 06] | D10: [parent06@example.com] | E10: 0 | F10: 0 | G10: 0 | H10: 0 | I10: =SUM(E10:H10) -> 0 | J10: =IF(B10="","",(Income!$B$37+Income!$B$27+Income!$B$28+Income!$B$29)-I10) -> 808.82 | K10: Pending
A11: #07 | B11: [Player 07 Legal Name] | C11: [Parent / Guardian of Player 07] | D11: [parent07@example.com] | E11: 0 | F11: 0 | G11: 0 | H11: 0 | I11: =SUM(E11:H11) -> 0 | J11: =IF(B11="","",(Income!$B$37+Income!$B$27+Income!$B$28+Income!$B$29)-I11) -> 808.82 | K11: Pending
A12: #08 | B12: [Player 08 Legal Name] | C12: [Parent / Guardian of Player 08] | D12: [parent08@example.com] | E12: 0 | F12: 0 | G12: 0 | H12: 0 | I12: =SUM(E12:H12) -> 0 | J12: =IF(B12="","",(Income!$B$37+Income!$B$27+Income!$B$28+Income!$B$29)-I12) -> 808.82 | K12: Pending
A13: #09 | B13: [Player 09 Legal Name] | C13: [Parent / Guardian of Player 09] | D13: [parent09@example.com] | E13: 0 | F13: 0 | G13: 0 | H13: 0 | I13: =SUM(E13:H13) -> 0 | J13: =IF(B13="","",(Income!$B$37+Income!$B$27+Income!$B$28+Income!$B$29)-I13) -> 808.82 | K13: Pending
A14: #10 | B14: [Player 10 Legal Name] | C14: [Parent / Guardian of Player 10] | D14: [parent10@example.com] | E14: 0 | F14: 0 | G14: 0 | H14: 0 | I14: =SUM(E14:H14) -> 0 | J14: =IF(B14="","",(Income!$B$37+Income!$B$27+Income!$B$28+Income!$B$29)-I14) -> 808.82 | K14: Pending
A15: #11 | B15: [Player 11 Legal Name] | C15: [Parent / Guardian of Player 11] | D15: [parent11@example.com] | E15: 0 | F15: 0 | G15: 0 | H15: 0 | I15: =SUM(E15:H15) -> 0 | J15: =IF(B15="","",(Income!$B$37+Income!$B$27+Income!$B$28+Income!$B$29)-I15) -> 808.82 | K15: Pending
A16: #12 | B16: [Player 12 Legal Name] | C16: [Parent / Guardian of Player 12] | D16: [parent12@example.com] | E16: 0 | F16: 0 | G16: 0 | H16: 0 | I16: =SUM(E16:H16) -> 0 | J16: =IF(B16="","",(Income!$B$37+Income!$B$27+Income!$B$28+Income!$B$29)-I16) -> 808.82 | K16: Pending
... A21: #17 | B21: [Player 17 Legal Name] | C21: [Parent / Guardian of Player 17] | D21: [parent17@example.com] | E21: 0 | F21: 0 | G21: 0 | H21: 0 | I21: =SUM(E21:H21) -> 0 | J21: =IF(B21="","",(Income!$B$37+Income!$B$27+Income!$B$28+Income!$B$29)-I21) -> 808.82 | K21: Pending
A22: #18 | E22: 0 | F22: 0 | G22: 0 | H22: 0 | I22: =IF(B22="","",SUM(E22:H22)) | J22: =IF(B22="","",(Income!$B$37+Income!$B$27+Income!$B$28+Income!$B$29)-I22) | K22: =IF(B22="","","Pending")
A23: #19 | E23: 0 | F23: 0 | G23: 0 | H23: 0 | I23: =IF(B23="","",SUM(E23:H23)) | J23: =IF(B23="","",(Income!$B$37+Income!$B$27+Income!$B$28+Income!$B$29)-I23) | K23: =IF(B23="","","Pending")
A24: #20 | E24: 0 | F24: 0 | G24: 0 | H24: 0 | I24: =IF(B24="","",SUM(E24:H24)) | J24: =IF(B24="","",(Income!$B$37+Income!$B$27+Income!$B$28+Income!$B$29)-I24) | K24: =IF(B24="","","Pending")
A25: #21 | E25: 0 | F25: 0 | G25: 0 | H25: 0 | I25: =IF(B25="","",SUM(E25:H25)) | J25: =IF(B25="","",(Income!$B$37+Income!$B$27+Income!$B$28+Income!$B$29)-I25) | K25: =IF(B25="","","Pending")
B26: TOTALS: ACTIVE ROSTER | E26: =SUM(E5:E25) -> 0 | F26: =SUM(F5:F25) -> 0 | G26: =SUM(G5:G25) -> 0 | H26: =SUM(H5:H25) -> 0 | I26: =SUM(I5:I25) -> 0 | J26: =SUM(J5:J25) -> 13749.94 | K26: =COUNTA(B5:B25) & " Players Accounted For" -> 17 Players Accounted For
